Workbook

Sheet Product_Backlog
B1: Product Backlog — BlueMoon v1.0 | F1: Backlog được suy ra từ 05_Epic_UserStory.xlsx. Story Point là ước lượng ban đầu của nhóm phân tích, không phải kết quả Planning Poker. Planned Sprint lấy từ kế hoạch Sprint 1-3; các story Unplanned ở lại Product Backlog.
B2: Order | C2: US ID | D2: User Story | E2: Epic ID | F2: Epic Name | G2: Feature ID | H2: Feature Name | I2: Business Value | J2: MoSCoW | K2: Priority | L2: Story Points | M2: Dependencies | N2: Planned Sprint | O2: Status | P2: Source RAW ID | Q2: Notes
B3: 1 | C3: US-01 | D3: Là một người dùng hệ thống, tôi muốn đăng nhập bằng tài khoản đã được cấp, để chỉ người được phép mới vào được các chức năng quản lý. | E3: EPIC-01 | F3: Quản lý tài khoản và truy cập | G3: FEAT-01-01 | H3: Bảo mật đăng nhập và xác thực | I3: Chỉ người được phép mới vào được các chức năng quản lý | J3: Must | K3: High | L3: 3 | M3: None | N3: Sprint 1 | O3: Sprint Backlog | P3: RAW-001 | Q3: Lý do Must: Là cửa vào của hệ thống; mọi chức năng khác đều cần đến nó (RAW-001; hạng mục phạm vi v1.0). Tự đăng ký không thuộc v1.0 (OQ-01). Story Point: ước lượng ban đầu của nhóm phân tích, nhóm sẽ ước lượng lại. Kế hoạch Sprint (Sprint 1): Là cửa vào; mọi story khác đều cần người dùng đã đăng nhập.
B4: 2 | C4: US-02 (Technical Story) | D4: Là một thành viên Ban quản trị, tôi muốn thông tin đăng nhập được bảo vệ, không bị lộ và không bị dò đoán liên tục, để không ai đoán được mật khẩu hay đọc thẳng cơ sở dữ liệu để lấy dữ liệu tài chính và dữ liệu cá nhân. | E4: EPIC-01 | F4: Quản lý tài khoản và truy cập | G4: FEAT-01-01 | H4: Bảo mật đăng nhập và xác thực | I4: Không ai đoán được mật khẩu hay đọc thẳng cơ sở dữ liệu để lấy dữ liệu tài chính và dữ liệu cá nhân | J4: Must | K4: High | L4: 3 | M4: US-01 | N4: Sprint 1 | O4: Sprint Backlog | P4: RAW-022 | Q4: Lý do Must: Là lớp bảo vệ nền tảng cho dữ liệu tài chính và cá nhân; việc băm mật khẩu phải có trước khi lưu bất kỳ dữ liệu thật nào. Giới hạn khóa N = 5 và thời gian khóa là mục tiêu đề xuất, chưa chốt (NFR-001.3). Technical Story. Story Point: ước lượng ban đầu của nhóm phân tích, nhóm sẽ ước lượng lại. Kế hoạch Sprint (Sprint 1): Mật khẩu phải được băm trước khi có tài khoản nào ngoài tài khoản nạp sẵn; dựa trên US-01.
B5: 3 | C5: US-03 | D5: Là một người dùng hệ thống, tôi muốn đổi mật khẩu của chính mình, để thay được mật khẩu ban đầu hoặc mật khẩu đã bị lộ mà không cần nhờ ai khác. | E5: EPIC-01 | F5: Quản lý tài khoản và truy cập | G5: FEAT-01-02 | H5: Tự phục vụ tài khoản | I5: Thay được mật khẩu ban đầu hoặc mật khẩu đã bị lộ mà không cần nhờ ai khác | J5: Must | K5: High | L5: 2 | M5: US-01 | N5: Sprint 1 | O5: Sprint Backlog | P5: RAW-002 | Q5: Lý do Must: Là hạng mục phạm vi v1.0 được nêu rõ (đổi mật khẩu). Quy tắc mật khẩu (đề xuất: tối thiểu 8 ký tự) chưa chốt. Là story tham chiếu cho thang ước lượng (2 điểm). Story Point: ước lượng ban đầu của nhóm phân tích, nhóm sẽ ước lượng lại. Kế hoạch Sprint (Sprint 1): Là hạng mục phạm vi v1.0 được nêu rõ; nhỏ và chỉ cần US-01.
B6: 4 | C6: US-06 | D6: Là một thành viên Ban quản trị, tôi muốn thêm hộ gia đình mới với số căn hộ, chủ hộ, diện tích căn hộ và thông tin liên hệ, để hộ đó được tính phí đúng theo diện tích. | E6: EPIC-02 | F6: Quản lý hộ gia đình | G6: FEAT-02-01 | H6: Đăng ký hộ gia đình | I6: Hộ gia đình được tính phí đúng theo diện tích | J6: Must | K6: High | L6: 3 | M6: None | N6: Sprint 1 | O6: Sprint Backlog | P6: RAW-003 | Q6: Lý do Must: Hộ gia đình và diện tích là dữ liệu nền để tính khoản thu; là gốc của hầu hết các story sau. Việc nhập dữ liệu ban đầu từ Excel nằm ngoài dự án (AS-08, OQ-12). Story Point: ước lượng ban đầu của nhóm phân tích, nhóm sẽ ước lượng lại. Kế hoạch Sprint (Sprint 1): Là gốc của dữ liệu hộ; khoản thu, khoản phải thu và tìm kiếm đều phụ thuộc vào nó.
B7: 5 | C7: US-07 | D7: Là một thành viên Ban quản trị, tôi muốn xem chi tiết một hộ gia đình cùng danh sách nhân khẩu của hộ, để xem được ai đang ở trong căn hộ và các thông tin tính phí của hộ ở cùng một chỗ. | E7: EPIC-02 | F7: Quản lý hộ gia đình | G7: FEAT-02-02 | H7: Xem và cập nhật hộ gia đình | I7: Xem được ai đang ở trong căn hộ và các thông tin tính phí của hộ ở cùng một chỗ | J7: Must | K7: High | L7: 3 | M7: US-06 | N7: Sprint 1 | O7: Sprint Backlog | P7: RAW-004 | Q7: Lý do Must: Chức năng cốt lõi của v1.0: nhân sự phải thấy một hộ và nhân khẩu của hộ ở cùng một nơi. Hoạt động được với danh sách nhân khẩu trống; nhân khẩu đến từ US-10. Story Point: ước lượng ban đầu của nhóm phân tích, nhóm sẽ ước lượng lại. Kế hoạch Sprint (Sprint 1): Cần dữ liệu hộ gia đình và nhân khẩu được tạo trong sprint này.
B8: 6 | C8: US-08 | D8: Là một thành viên Ban quản trị, tôi muốn sửa diện tích, chủ hộ hoặc thông tin liên hệ của một hộ gia đình, để khoản thu được tính trên dữ liệu đúng và sai sót sửa được. | E8: EPIC-02 | F8: Quản lý hộ gia đình | G8: FEAT-02-02 | H8: Xem và cập nhật hộ gia đình | I8: Khoản thu được tính trên dữ liệu đúng và sai sót sửa được | J8: Must | K8: High | L8: 2 | M8: US-06 | N8: Sprint 1 | O8: Sprint Backlog | P8: RAW-004 | Q8: Lý do Must: Diện tích sai dẫn đến khoản thu sai (PP-03); sửa dữ liệu là nhu cầu cốt lõi về chất lượng dữ liệu. Ảnh hưởng đến các khoản phải thu đã sinh là chính sách đề xuất, chưa chốt (OQ-14). Story Point: ước lượng ban đầu của nhóm phân tích, nhóm sẽ ước lượng lại. Kế hoạch Sprint (Sprint 1): Sửa diện tích sớm giúp tránh khoản phải thu sai ở Sprint 2.
B9: 7 | C9: US-10 | D9: Là một thành viên Ban quản trị, tôi muốn thêm một nhân khẩu vào hộ gia đình với họ tên, ngày sinh, giới tính, quan hệ với chủ hộ và số giấy tờ tùy thân nếu có, để danh sách nhân khẩu của hộ đầy đủ, dùng được ngay khi cần báo cáo. | E9: EPIC-03 | F9: Quản lý nhân khẩu | G9: FEAT-03-01 | H9: Hồ sơ nhân khẩu | I9: Danh sách nhân khẩu của hộ đầy đủ, dùng được ngay khi cần báo cáo | J9: Must | K9: High | L9: 3 | M9: US-06 | N9: Sprint 1 | O9: Sprint Backlog | P9: RAW-006 | Q9: Lý do Must: Quản lý nhân khẩu là hạng mục phạm vi v1.0 và là yêu cầu nêu rõ trong đề bài. Số giấy tờ tùy thân là tùy chọn (OQ-08). Story Point: ước lượng ban đầu của nhóm phân tích, nhóm sẽ ước lượng lại. Kế hoạch Sprint (Sprint 1): Dữ liệu nhân khẩu dựa trên hộ gia đình; biến động và tạm trú cần nó.
B10: 8 | C10: US-11 | D10: Là một thành viên Ban quản trị, tôi muốn cập nhật thông tin của một nhân khẩu, để hồ sơ nhân khẩu luôn đúng và người đã rời đi không bị xóa khỏi hệ thống. | E10: EPIC-03 | F10: Quản lý nhân khẩu | G10: FEAT-03-01 | H10: Hồ sơ nhân khẩu | I10: Hồ sơ nhân khẩu luôn đúng và người đã rời đi không bị xóa khỏi hệ thống | J10: Must | K10: High | L10: 2 | M10: US-10 | N10: Sprint 1 | O10: Sprint Backlog | P10: RAW-006 | Q10: Lý do Must: Cần để giữ hồ sơ nhân khẩu đúng; cùng hạng mục phạm vi với US-10. Không xóa cứng; việc rời đi được ghi bằng một biến động (US-12). Story Point: ước lượng ban đầu của nhóm phân tích, nhóm sẽ ước lượng lại. Kế hoạch Sprint (Sprint 1): Cùng dữ liệu với US-10; hoàn thiện việc cập nhật nhân khẩu.
B11: 9 | C11: US-12 | D11: Là một thành viên Ban quản trị, tôi muốn ghi nhận nhân khẩu chuyển đến, chuyển đi, sinh hoặc mất kèm ngày và lý do, để danh sách nhân khẩu từng hộ và tổng số nhân khẩu đúng với thực tế ở ngày cần xem. | E11: EPIC-03 | F11: Quản lý nhân khẩu | G11: FEAT-03-02 | H11: Biến động nhân khẩu | I11: Danh sách nhân khẩu từng hộ và tổng số nhân khẩu đúng với thực tế ở ngày cần xem | J11: Must | K11: High | L11: 5 | M11: US-10 | N11: Sprint 1 | O11: Sprint Backlog | P11: RAW-007 | Q11: Lý do Must: Biến động nhân khẩu được nêu trong đề bài và quyết định trạng thái nhân khẩu theo ngày. Các loại biến động là danh sách đề xuất (OQ-13). Logic theo ngày hiệu lực là phần việc chính. Story Point: ước lượng ban đầu của nhóm phân tích, nhóm sẽ ước lượng lại. Kế hoạch Sprint (Sprint 1): Là story lớn nhất của Sprint 1; bắt đầu sớm để có thời gian rà soát và sửa lỗi.
B12: 10 | C12: US-14 | D12: Là một thành viên Ban quản trị, tôi muốn ghi nhận tạm trú hoặc tạm vắng của một nhân khẩu kèm ngày bắt đầu, ngày kết thúc và lý do, để biết rõ tình trạng cư trú của từng người và phát hiện được các trường hợp đã hết hạn. | E12: EPIC-03 | F12: Quản lý nhân khẩu | G12: FEAT-03-03 | H12: Tạm trú và tạm vắng | I12: Biết rõ tình trạng cư trú của từng người và phát hiện được các trường hợp đã hết hạn | J12: Must | K12: High | L12: 3 | M12: US-10 | N12: Sprint 1 | O12: Sprint Backlog | P12: RAW-008 | Q12: Lý do Must: Tạm trú và tạm vắng được nêu trong đề bài (RAW-008). Các biểu mẫu pháp lý nằm ngoài phạm vi (OQ-07). Story Point: ước lượng ban đầu của nhóm phân tích, nhóm sẽ ước lượng lại. Kế hoạch Sprint (Sprint 1): Hoàn thiện phần quản lý nhân khẩu được nêu trong đề bài.
B13: 11 | C13: US-16 | D13: Là một thành viên Ban quản trị, tôi muốn tạo một khoản thu với tên, loại (bắt buộc hoặc tự nguyện), kỳ thu hoặc đợt thu, đơn giá hoặc số tiền, và hạn nộp, để các khoản tiền hộ phải đóng hoặc có thể đóng chỉ cần khai báo một lần trong hệ thống. | E13: EPIC-04 | F13: Quản lý khoản thu | G13: FEAT-04-01 | H13: Định nghĩa khoản thu | I13: Các khoản tiền hộ phải đóng hoặc có thể đóng chỉ cần khai báo một lần trong hệ thống | J13: Must | K13: High | L13: 3 | M13: None | N13: Sprint 2 | O13: Sprint Backlog | P13: RAW-010 | Q13: Lý do Must: Quản lý khoản thu là hạng mục phạm vi v1.0; không thể bắt đầu thu phí khi chưa có khoản thu được định nghĩa. Miễn giảm và đơn giá riêng cho kiot hoặc penthouse không thuộc v1.0 (OQ-02, OQ-03). Story Point: ước lượng ban đầu của nhóm phân tích, nhóm sẽ ước lượng lại. Kế hoạch Sprint (Sprint 2): Khoản thu phải có trước khi sinh khoản phải thu hay ghi nhận thanh toán. Không phụ thuộc Sprint 1 ngoài đăng nhập.
B14: 12 | C14: US-17 | D14: Là một thành viên Ban quản trị, tôi muốn thay đổi đơn giá hoặc hạn nộp của một khoản thu và ngừng áp dụng một khoản thu, để khoản thu cập nhật theo quyết định của Ban và thay đổi đơn giá, mà hồ sơ cũ vẫn còn. | E14: EPIC-04 | F14: Quản lý khoản thu | G14: FEAT-04-01 | H14: Định nghĩa khoản thu | I14: Khoản thu cập nhật theo quyết định của Ban và thay đổi đơn giá, mà hồ sơ cũ vẫn còn | J14: Must | K14: High | L14: 3 | M14: US-16 | N14: Sprint 2 | O14: Sprint Backlog | P14: RAW-010 | Q14: Lý do Must: Đơn giá do Ban quản trị quyết định và có thay đổi; đơn giá sai phải sửa được mà không mất lịch sử. Đơn giá không được ghi đè lên các khoản phải thu trong quá khứ (AC-US17-01). Story Point: ước lượng ban đầu của nhóm phân tích, nhóm sẽ ước lượng lại. Kế hoạch Sprint (Sprint 2): Việc lưu phiên bản đơn giá phải có trước khi sinh khoản phải thu.
... B43: 41 | C43: US-37 | D43: Là một quản trị hệ thống, tôi muốn tìm và xem nhật ký thao tác theo người dùng, ngày và đối tượng, để kiểm tra lại được khi có tranh chấp về dữ liệu bị thay đổi. | E43: EPIC-07 | F43: An toàn dữ liệu, truy vết và chất lượng nền tảng | G43: FEAT-07-02 | H43: Nhật ký thao tác | I43: Kiểm tra lại được khi có tranh chấp về dữ liệu bị thay đổi | J43: Could | K43: Low | L43: 3 | M43: US-36, US-05 | N43: Unplanned | O43: Product Backlog | P43: RAW-025 | Q43: Lý do Could: Xem nhật ký là tính năng nên có khi US-36 đã ghi lại. Chỉ quản trị viên mới mở được. Story Point: ước lượng ban đầu của nhóm phân tích, nhóm sẽ ước lượng lại. Không nằm trong Sprint 1-3: Could. Phụ thuộc US-36, vốn chưa được xếp kế hoạch.
C46: SUMMARY | F46: SPRINT PLAN | G46: Stories | H46: Story Points
C47: Product Backlog items | D47: =COUNTA(C3:C43) -> 41 | F47: Sprint 1 | G47: =COUNTIF($N$3:$N$43,"Sprint 1") -> 11 | H47: =SUMIF($N$3:$N$43,"Sprint 1",$L$3:$L$43) -> 34
C48: Must | D48: =COUNTIF(J3:J43,"Must") -> 21 | F48: Sprint 2 | G48: =COUNTIF($N$3:$N$43,"Sprint 2") -> 10 | H48: =SUMIF($N$3:$N$43,"Sprint 2",$L$3:$L$43) -> 37
C49: Should | D49: =COUNTIF(J3:J43,"Should") -> 18 | F49: Sprint 3 | G49: =COUNTIF($N$3:$N$43,"Sprint 3") -> 10 | H49: =SUMIF($N$3:$N$43,"Sprint 3",$L$3:$L$43) -> 35
C50: Could | D50: =COUNTIF(J3:J43,"Could") -> 2 | F50: Unplanned (ở lại Product Backlog) | G50: =COUNTIF($N$3:$N$43,"Unplanned") -> 10 | H50: =SUMIF($N$3:$N$43,"Unplanned",$L$3:$L$43) -> 37
C51: Won't (stories) | D51: =COUNTIF(J3:J43,"Won't") -> 0 | F51: Roadmap (v2.0, không có story) | G51: =COUNTIF($N$3:$N$43,"Roadmap") -> 0 | H51: =SUMIF($N$3:$N$43,"Roadmap",$L$3:$L$43) -> 0
C52: Total Story Points | D52: =SUM(L3:L43) -> 143
C54: Roadmap v2.0 (phí gửi xe; điện, nước, internet) không thuộc backlog này hay Sprint 1-3: không có User Story, là Won't-have cho v1.0 và chỉ được liệt kê ở sheet Traceability (RAW-029, RAW-030) với Planned Sprint = Roadmap.

Sheet Traceability
B1: Traceability Matrix — RAW to Acceptance Criteria | F1: Chuỗi: RAW > Epic > Feature > User Story > Acceptance Criteria. Mỗi dòng là một cặp RAW và User Story. Nội dung RAW là nguồn từ báo cáo phỏng vấn và không bị thay đổi.
B2: RAW ID | C2: RAW Requirement | D2: Epic ID | E2: Feature ID | F2: US ID | G2: User Story | H2: Acceptance Criteria | I2: MoSCoW | J2: Story Points | K2: Planned Sprint | L2: Status | M2: Notes
B3: RAW-001 | C3: Hệ thống cho phép Ban quản trị đăng nhập bằng tài khoản được cấp sẵn (tên đăng nhập, mật khẩu); các chức năng quản lý chỉ truy cập được sau khi đăng nhập thành công. | D3: EPIC-01 | E3: FEAT-01-01 | F3: US-01 | G3: Là một người dùng hệ thống, tôi muốn đăng nhập bằng tài khoản đã được cấp, để chỉ người được phép mới vào được các chức năng quản lý. | H3: AC-US01-01 Given một tài khoản đã được cấp cho người dùng, và tên đăng nhập cùng mật khẩu đều đúng When người dùng gửi form đăng nhập Then hệ thống mở màn hình chính, chỉ hiển thị các chức năng mà tài khoản đó được phép dùng AC-US01-02 Given tên đăng nhập sai hoặc mật khẩu sai When người dùng gửi form đăng nhập Then hệ thống từ chối đăng nhập bằng một thông báo chung, không nói rõ trường nào bị sai And không có phiên đăng nhập nào được tạo AC-US01-03 Given người dùng chưa đăng nhập When người dùng cố mở một chức năng quản lý bất kỳ (hộ gia đình, nhân khẩu, khoản thu, thanh toán, tìm kiếm hoặc thống kê) Then hệ thống từ chối truy cập và hiển thị màn hình đăng nhập | I3: Must | J3: 3 | K3: Sprint 1 | L3: Sprint Backlog | M3: IN_SCOPE. Không có tự đăng ký: tài khoản do Ban quản trị cấp (AS-03, OQ-01). Nhóm bổ sung US-41 khi lập Product Backlog để quản trị viên tạo tài khoản ngay trong hệ thống; một tài khoản quản trị ban đầu được nạp sẵn cho buổi demo (giả định).
B4: RAW-001 | C4: Hệ thống cho phép Ban quản trị đăng nhập bằng tài khoản được cấp sẵn (tên đăng nhập, mật khẩu); các chức năng quản lý chỉ truy cập được sau khi đăng nhập thành công. | D4: EPIC-01 | E4: FEAT-01-04 | F4: US-41 | G4: Là một quản trị hệ thống, tôi muốn tạo và vô hiệu hóa tài khoản cho nhân sự Ban quản trị và đặt mật khẩu mới cho người dùng quên mật khẩu, để chỉ người do Ban quản trị chọn mới đăng nhập được và nhân sự quên mật khẩu không bị khóa ngoài hệ thống. | H4: AC-US41-01 Given một quản trị hệ thống đã đăng nhập, nhập tên đăng nhập không trùng, tên hiển thị, mật khẩu ban đầu đạt quy tắc mật khẩu và một vai trò đã định nghĩa ở US-05 When quản trị viên lưu Then tài khoản được tạo và người dùng đăng nhập được bằng mật khẩu ban đầu AC-US41-02 Given tên đăng nhập đã tồn tại When quản trị viên lưu Then không có tài khoản nào được tạo và thông báo chỉ ra tên đăng nhập bị trùng AC-US41-03 Given một tài khoản bị quản trị viên vô hiệu hóa When người dùng của tài khoản đó cố đăng nhập Then hệ thống từ chối đăng nhập And dữ liệu tài khoản và lịch sử của tài khoản được giữ lại (không xóa cứng, AS-17) AC-US41-04 Given một người dùng đã quên mật khẩu When quản trị viên đặt mật khẩu tạm thời mới cho tài khoản đó Then người dùng đăng nhập được bằng mật khẩu đó và mật khẩu cũ không còn dùng được And mọi trạng thái khóa do đăng nhập sai của tài khoản đó được gỡ bỏ | I4: Should | J4: 5 | K4: Sprint 2 | L4: Sprint Backlog | M4: IN_SCOPE. Không có tự đăng ký: tài khoản do Ban quản trị cấp (AS-03, OQ-01). Nhóm bổ sung US-41 khi lập Product Backlog để quản trị viên tạo tài khoản ngay trong hệ thống; một tài khoản quản trị ban đầu được nạp sẵn cho buổi demo (giả định).
B5: RAW-002 | C5: Người dùng tự đổi mật khẩu của mình và xem, cập nhật thông tin cá nhân của tài khoản. | D5: EPIC-01 | E5: FEAT-01-02 | F5: US-03 | G5: Là một người dùng hệ thống, tôi muốn đổi mật khẩu của chính mình, để thay được mật khẩu ban đầu hoặc mật khẩu đã bị lộ mà không cần nhờ ai khác. | H5: AC-US03-01 Given người dùng đã đăng nhập, nhập đúng mật khẩu hiện tại và một mật khẩu mới đạt quy tắc mật khẩu (đề xuất: tối thiểu 8 ký tự, chưa chốt) cùng phần xác nhận trùng khớp When người dùng lưu thay đổi Then mật khẩu được đổi And lần đăng nhập tiếp theo yêu cầu dùng mật khẩu mới AC-US03-02 Given người dùng nhập sai mật khẩu hiện tại When người dùng lưu thay đổi Then hệ thống từ chối thay đổi và mật khẩu giữ nguyên AC-US03-03 Given mật khẩu mới và phần xác nhận khác nhau, hoặc mật khẩu mới vi phạm quy tắc mật khẩu When người dùng lưu thay đổi Then hệ thống từ chối thay đổi và thông báo rõ vấn đề hoặc quy tắc | I5: Must | J5: 2 | K5: Sprint 1 | L5: Sprint Backlog | M5: IN_SCOPE. Tách thành đổi mật khẩu (Must) và thông tin cá nhân (Should). Các trường hồ sơ vẫn cần xác nhận.
B6: RAW-002 | C6: Người dùng tự đổi mật khẩu của mình và xem, cập nhật thông tin cá nhân của tài khoản. | D6: EPIC-01 | E6: FEAT-01-02 | F6: US-04 | G6: Là một người dùng hệ thống, tôi muốn xem và cập nhật thông tin cá nhân của chính tài khoản mình, để hồ sơ tài khoản của Ban quản trị luôn đúng và mọi thao tác đều gắn được với một người cụ thể. | H6: AC-US04-01 Given người dùng đã đăng nhập When người dùng mở màn hình thông tin tài khoản Then thông tin cá nhân hiện tại của tài khoản đó được hiển thị (các trường cần xác nhận, ví dụ tên hiển thị và thông tin liên hệ) AC-US04-02 Given người dùng thay đổi thông tin bằng các giá trị hợp lệ When người dùng lưu thay đổi Then thay đổi được lưu lại và hiển thị ở lần mở màn hình tiếp theo AC-US04-03 Given một trường bắt buộc bị để trống When người dùng lưu thay đổi Then không có gì được lưu và thông báo nêu rõ trường còn thiếu | I6: Should | J6: 2 | K6: Unplanned | L6: Product Backlog | M6: IN_SCOPE. Tách thành đổi mật khẩu (Must) và thông tin cá nhân (Should). Các trường hồ sơ vẫn cần xác nhận.
B7: RAW-003 | C7: BQT muốn lưu thông tin hộ gia đình tập trung và tránh trường hợp nhập trùng căn hộ. | D7: EPIC-02 | E7: FEAT-02-01 | F7: US-06 | G7: Là một thành viên Ban quản trị, tôi muốn thêm hộ gia đình mới với số căn hộ, chủ hộ, diện tích căn hộ và thông tin liên hệ, để hộ đó được tính phí đúng theo diện tích. | H7: AC-US06-01 Given người dùng có quyền và nhập số căn hộ, chủ hộ, diện tích lớn hơn 0 m² và thông tin liên hệ When người dùng lưu thay đổi Then hộ gia đình được tạo và xuất hiện trong danh sách hộ AC-US06-02 Given số căn hộ đã tồn tại When người dùng lưu thay đổi Then hộ gia đình không được tạo và thông báo chỉ ra số căn hộ bị trùng AC-US06-03 Given một trường bắt buộc bị trống hoặc diện tích bằng 0, âm hoặc không phải số When người dùng lưu thay đổi Then không có gì được lưu và thông báo nêu rõ trường không hợp lệ | I7: Must | J7: 3 | K7: Sprint 1 | L7: Sprint Backlog | M7: IN_SCOPE. Việc nhập dữ liệu ban đầu từ Excel nằm ngoài dự án (AS-08, C-08, OQ-12).
B8: RAW-004 | C8: Cho phép xem chi tiết và sửa thông tin hộ gia đình (diện tích, chủ hộ, liên hệ), kèm danh sách nhân khẩu của hộ. | D8: EPIC-02 | E8: FEAT-02-02 | F8: US-07 | G8: Là một thành viên Ban quản trị, tôi muốn xem chi tiết một hộ gia đình cùng danh sách nhân khẩu của hộ, để xem được ai đang ở trong căn hộ và các thông tin tính phí của hộ ở cùng một chỗ. | H8: AC-US07-01 Given một hộ gia đình tồn tại When người dùng mở chi tiết hộ đó Then số căn hộ, chủ hộ, diện tích và thông tin liên hệ được hiển thị cùng danh sách nhân khẩu và tình trạng cư trú của họ AC-US07-02 Given một hộ gia đình chưa có nhân khẩu nào được ghi nhận When người dùng mở chi tiết hộ đó Then hệ thống hiển thị thông báo danh sách trống thay vì báo lỗi | I8: Must | J8: 3 | K8: Sprint 1 | L8: Sprint Backlog | M8: NEEDS_CLARIFICATION. OQ-14: ảnh hưởng của việc đổi diện tích đến các khoản phải thu đã tạo. Story dùng một chính sách đề xuất được đánh dấu TBD. Phần chồng lấn một phần với RAW-006 (danh sách nhân khẩu trên màn hình hộ) được xử lý bằng cách giữ việc sửa nhân khẩu trong EPIC-03.
B9: RAW-004 | C9: Cho phép xem chi tiết và sửa thông tin hộ gia đình (diện tích, chủ hộ, liên hệ), kèm danh sách nhân khẩu của hộ. | D9: EPIC-02 | E9: FEAT-02-02 | F9: US-08 | G9: Là một thành viên Ban quản trị, tôi muốn sửa diện tích, chủ hộ hoặc thông tin liên hệ của một hộ gia đình, để khoản thu được tính trên dữ liệu đúng và sai sót sửa được. | H9: AC-US08-01 Given một hộ gia đình tồn tại When người dùng thay đổi thông tin bằng các giá trị hợp lệ và lưu Then thay đổi được lưu và hiển thị trong chi tiết hộ gia đình AC-US08-02 Given diện tích bị đổi thành 0, số âm hoặc để trống, hoặc một trường bắt buộc bị trống When người dùng lưu thay đổi Then hệ thống từ chối thay đổi và giữ nguyên dữ liệu gốc AC-US08-03 Given diện tích của một hộ gia đình bị thay đổi When người dùng lưu thay đổi Then diện tích mới chỉ được dùng cho các khoản phải thu sinh ra sau đó và các thanh toán đã ghi nhận không bị thay đổi (chính sách đề xuất, chưa chốt, OQ-14) | I9: Must | J9: 2 | K9: Sprint 1 | L9: Sprint Backlog | M9: NEEDS_CLARIFICATION. OQ-14: ảnh hưởng của việc đổi diện tích đến các khoản phải thu đã tạo. Story dùng một chính sách đề xuất được đánh dấu TBD. Phần chồng lấn một phần với RAW-006 (danh sách nhân khẩu trên màn hình hộ) được xử lý bằng cách giữ việc sửa nhân khẩu trong EPIC-03.
B10: RAW-005 | C10: Cho phép ghi nhận đổi chủ hộ hoặc hộ chuyển đi / ngừng cư trú mà vẫn lưu lịch sử, không xóa dữ liệu cũ. | D10: EPIC-02 | E10: FEAT-02-03 | F10: US-09 | G10: Là một thành viên Ban quản trị, tôi muốn ghi nhận việc đổi chủ hộ hoặc hộ chuyển đi mà vẫn giữ thông tin cũ, để lịch sử chủ sở hữu luôn có sẵn khi cần giải đáp về khoản thu hoặc yêu cầu của cơ quan chức năng. | H10: AC-US09-01 Given một hộ gia đình tồn tại When người dùng ghi nhận một chủ hộ mới kèm ngày hiệu lực Then chủ hộ mới được hiển thị là chủ hộ hiện tại And chủ hộ trước đó vẫn nằm trong lịch sử của hộ cùng các mốc ngày AC-US09-02 Given một hộ gia đình tồn tại When người dùng ghi nhận hộ đã chuyển đi kèm ngày và lý do Then hộ được đánh dấu là đã chuyển đi với ngày đó And không có dữ liệu hộ hoặc nhân khẩu nào bị xóa And hộ vẫn tìm thấy được bằng tìm kiếm AC-US09-03 Given một hộ gia đình có các thay đổi đã được ghi nhận When người dùng mở lịch sử của hộ Then các thay đổi được liệt kê theo thứ tự thời gian cùng ngày tương ứng | I10: Should | J10: 5 | K10: Unplanned | L10: Product Backlog | M10: IN_SCOPE. Chồng lấn một phần với RAW-007. Ranh giới: RAW-005 ở cấp hộ (chủ hộ, hộ chuyển đi); RAW-007 là biến động ở cấp nhân khẩu.
B11: RAW-006 | C11: BQT muốn quản lý thông tin những người thuộc từng hộ và vẫn tra cứu được người đã rời đi. | D11: EPIC-03 | E11: FEAT-03-01 | F11: US-10 | G11: Là một thành viên Ban quản trị, tôi muốn thêm một nhân khẩu vào hộ gia đình với họ tên, ngày sinh, giới tính, quan hệ với chủ hộ và số giấy tờ tùy thân nếu có, để danh sách nhân khẩu của hộ đầy đủ, dùng được ngay khi cần báo cáo. | H11: AC-US10-01 Given một hộ gia đình tồn tại và người dùng nhập họ tên, ngày sinh, giới tính và quan hệ với chủ hộ When người dùng lưu thay đổi Then nhân khẩu được thêm vào hộ đó và xuất hiện trong danh sách nhân khẩu của hộ AC-US10-02 Given thiếu một trường bắt buộc When người dùng lưu thay đổi Then không có gì được lưu và thông báo nêu rõ trường còn thiếu AC-US10-03 Given không cung cấp số giấy tờ tùy thân (trường này là tùy chọn, OQ-08) When người dùng lưu thay đổi Then nhân khẩu vẫn được lưu mà không có số giấy tờ | I11: Must | J11: 3 | K11: Sprint 1 | L11: Sprint Backlog | M11: IN_SCOPE. Số giấy tờ tùy chọn (OQ-08); các trường nhân khẩu theo AS-18.
B12: RAW-006 | C12: BQT muốn quản lý thông tin những người thuộc từng hộ và vẫn tra cứu được người đã rời đi. | D12: EPIC-03 | E12: FEAT-03-01 | F12: US-11 | G12: Là một thành viên Ban quản trị, tôi muốn cập nhật thông tin của một nhân khẩu, để hồ sơ nhân khẩu luôn đúng và người đã rời đi không bị xóa khỏi hệ thống. | H12: AC-US11-01 Given một nhân khẩu tồn tại When người dùng thay đổi thông tin bằng các giá trị hợp lệ và lưu Then thay đổi được lưu và hiển thị trong hồ sơ nhân khẩu AC-US11-02 Given một trường bắt buộc bị đặt thành trống When người dùng lưu thay đổi Then hệ thống từ chối thay đổi và giữ nguyên dữ liệu trước đó AC-US11-03 Given một nhân khẩu đã rời khỏi hộ When người dùng tìm cách xóa nhân khẩu đó Then không tồn tại chức năng xóa cứng và nhân khẩu chỉ có thể được đánh dấu là đã rời đi thông qua một bản ghi biến động And nhân khẩu vẫn nằm trong lịch sử | I12: Must | J12: 2 | K12: Sprint 1 | L12: Sprint Backlog | M12: IN_SCOPE. Số giấy tờ tùy chọn (OQ-08); các trường nhân khẩu theo AS-18.
B13: RAW-007 | C13: BQT muốn theo dõi các thay đổi nhân khẩu của từng hộ theo thời gian. | D13: EPIC-03 | E13: FEAT-03-02 | F13: US-12 | G13: Là một thành viên Ban quản trị, tôi muốn ghi nhận nhân khẩu chuyển đến, chuyển đi, sinh hoặc mất kèm ngày và lý do, để danh sách nhân khẩu từng hộ và tổng số nhân khẩu đúng với thực tế ở ngày cần xem. | H13: AC-US12-01 Given một hộ gia đình tồn tại When người dùng ghi nhận một lần chuyển đến hoặc một lần sinh kèm ngày hiệu lực và lý do Then người đó được thêm làm nhân khẩu của hộ từ ngày đó And một bản ghi biến động được lưu AC-US12-02 Given một nhân khẩu tồn tại When người dùng ghi nhận một lần chuyển đi hoặc một trường hợp mất kèm ngày hiệu lực và lý do Then nhân khẩu được đánh dấu là đã rời đi từ ngày đó và không bị xóa And một bản ghi biến động được lưu AC-US12-03 Given thiếu ngày hiệu lực When người dùng lưu thay đổi Then không có gì được lưu và thông báo nêu rõ ngày là bắt buộc | I13: Must | J13: 5 | K13: Sprint 1 | L13: Sprint Backlog | M13: NEEDS_CLARIFICATION. OQ-13: danh sách loại biến động và hạn cập nhật. Story dùng chuyển đến, chuyển đi, sinh, mất làm danh sách đề xuất.
B14: RAW-007 | C14: BQT muốn theo dõi các thay đổi nhân khẩu của từng hộ theo thời gian. | D14: EPIC-03 | E14: FEAT-03-02 | F14: US-13 | G14: Là một thành viên Ban quản trị, tôi muốn xem lịch sử biến động của một hộ gia đình hoặc của một nhân khẩu, để trả lời được cư dân và cơ quan chức năng khi họ hỏi ai đã ở đó và vào lúc nào. | H14: AC-US13-01 Given một hộ gia đình có các biến động đã được ghi nhận When người dùng mở lịch sử biến động của hộ Then mỗi dòng hiển thị ngày, loại và lý do theo thứ tự thời gian AC-US13-02 Given một nhân khẩu có các biến động đã được ghi nhận When người dùng mở lịch sử biến động của nhân khẩu Then chỉ hiển thị các dòng của nhân khẩu đó AC-US13-03 Given chưa có biến động nào được ghi nhận When người dùng mở một lịch sử Then hệ thống hiển thị thông báo chưa có biến động nào được ghi nhận | I14: Should | J14: 2 | K14: Unplanned | L14: Product Backlog | M14: NEEDS_CLARIFICATION. OQ-13: danh sách loại biến động và hạn cập nhật. Story dùng chuyển đến, chuyển đi, sinh, mất làm danh sách đề xuất.
... B44: RAW-028 | C44: Người dùng muốn giao diện tiếng Việt, dễ hiểu và thao tác thu phí đơn giản. | D44: EPIC-07 | E44: FEAT-07-04 | F44: US-40 | G44: Là một thành viên Ban quản trị, tôi muốn ứng dụng dùng tiếng Việt, hiển thị tiền VND dễ đọc và có thông báo lỗi rõ ràng, để nhân sự không chuyên CNTT dùng được sau một buổi hướng dẫn ngắn. | H44: AC-US40-01 Given bất kỳ màn hình nào của ứng dụng When màn hình được hiển thị Then mọi nhãn, menu và thông báo đều bằng tiếng Việt [NFR-007.1] AC-US40-02 Given một số tiền được hiển thị trên màn hình, biên lai hoặc thống kê When màn hình được hiển thị Then số tiền dùng dấu phân tách hàng nghìn và đơn vị VND [NFR-007.2] AC-US40-03 Given một lỗi nhập liệu như thiếu trường, trùng số căn hộ hoặc số tiền không hợp lệ When lỗi xảy ra Then thông báo nêu nguyên nhân và cách khắc phục [NFR-007.3] AC-US40-04 Given một thành viên nhóm hoặc bạn cùng lớp không viết mã đóng vai thành viên Ban quản trị When người đó hoàn thành kịch bản thanh toán chuẩn sau một buổi hướng dẫn ngắn Then kịch bản được hoàn thành (mục tiêu chưa chốt, đề xuất trong 10 phút) và kết quả được ghi là chạy thử theo kịch bản role-play, không phải kiểm thử với người dùng thật [NFR-007.5] | I44: Should | J44: 3 | K44: Sprint 3 | L44: Sprint Backlog | M44: IN_SCOPE. Technical Story và acceptance criteria của story ghi nhận thanh toán; mục tiêu 5 bước là đề xuất.
B45: RAW-029 | C45: [Roadmap v2.0] Quản lý phí gửi xe: thu theo tháng theo thông tin phương tiện đăng ký của hộ gia đình. | D45: — | E45: — | F45: — | G45: — (không có User Story) | H45: — | I45: Won't | J45: — | K45: Roadmap | L45: Roadmap | M45: ROADMAP. Won't-have cho v1.0. Không tạo Epic, Feature hay User Story. Số tiền phí gửi xe trong đề bài cần được xác nhận.
B46: RAW-030 | C46: [Roadmap v2.0] Quản lý các khoản thu hộ điện, nước, internet theo thông báo của nhà cung cấp dịch vụ. | D46: — | E46: — | F46: — | G46: — (không có User Story) | H46: — | I46: Won't | J46: — | K46: Roadmap | L46: Roadmap | M46: ROADMAP. Won't-have cho v1.0. Không tạo Epic, Feature hay User Story.
C49: COVERAGE
C50: Tổng số RAW requirement | D50: 30
C51: RAW hợp lệ cho v1.0 (không tính ROADMAP) | D51: 28
C52: RAW hợp lệ đã truy vết đến một User Story | D52: 28
C53: Mức truy vết của RAW hợp lệ | D53: 100%
C54: RAW có User Story / tất cả RAW | D54: 28 / 30 (93.3%)
C55: RAW chưa có User Story | D55: RAW-029 (ROADMAP), RAW-030 (ROADMAP)
C56: RAW hợp lệ có ít nhất một story trong Sprint 1-3 | D56: 24/28
C57: RAW hợp lệ chỉ liên kết với các story chưa xếp Sprint | D57: RAW-005, RAW-009, RAW-021, RAW-025

Sheet Sprint_1
B1: Sprint 1 — Nền tảng, tài khoản, quản lý hộ gia đình và nhân khẩu
B2: Ước lượng tính theo giờ (số nguyên) và là ước lượng lập kế hoạch ban đầu. Các task được liệt kê theo thứ tự làm việc. Mọi task bắt đầu ở trạng thái Todo; chưa có task nào được đánh dấu Done.
B3: Sprint Name | D3: Sprint 1 — Nền tảng, tài khoản, quản lý hộ gia đình và nhân khẩu
B4: Sprint Goal | D4: Có nền tảng chạy được cho nhân sự Ban quản trị: đăng nhập, đổi mật khẩu, và quản lý hồ sơ hộ gia đình, nhân khẩu (gồm chuyển đến/đi, sinh, mất, tạm trú). Công việc thu phí sau này bắt đầu từ dữ liệu này nên dữ liệu phải đúng.
B5: Expected Increment | D5: Một ứng dụng desktop chạy được, kết nối MySQL, có cửa sổ chính và điều hướng. Đăng nhập bằng tài khoản quản trị nạp sẵn, khóa tài khoản sau nhiều lần thất bại, đổi mật khẩu và menu theo vai trò. Có thể thêm, xem và sửa hộ gia đình. Có thể thêm và cập nhật nhân khẩu; ghi nhận được biến động và tạm trú. Có bộ dữ liệu giả để trình diễn. Mọi story được Product Owner nghiệm thu theo Acceptance Criteria.
B6: Total Story Points | D6: =SUM(E12:E22) -> 34
B7: Total Estimate (hours) | D7: =SUM(G26:G80) -> 202
B8: Stories / Tasks | D8: 11 story, 55 task
B9: Sprint length and dates | D9: Chưa chốt. docs/02 đề xuất một tuần, nhưng độ dài và hạn nộp vẫn là câu hỏi mở (SQ-02). Kế hoạch này không giả định ngày nào.
B10: Các story cam kết trong sprint này (từ Product_Backlog)
B11: US ID | C11: MoSCoW | D11: User Story | E11: Story Points | F11: Why in this sprint
B12: US-01 | C12: Must | D12: Là một người dùng hệ thống, tôi muốn đăng nhập bằng tài khoản đã được cấp, để chỉ người được phép mới vào được các chức năng quản lý. | E12: 3 | F12: Là cửa vào; mọi story khác đều cần người dùng đã đăng nhập.
B13: US-02 | C13: Must | D13: Là một thành viên Ban quản trị, tôi muốn thông tin đăng nhập được bảo vệ, không bị lộ và không bị dò đoán liên tục, để không ai đoán được mật khẩu hay đọc thẳng cơ sở dữ liệu để lấy dữ liệu tài chính và dữ liệu cá nhân. | E13: 3 | F13: Mật khẩu phải được băm trước khi có tài khoản nào ngoài tài khoản nạp sẵn; dựa trên US-01.
B14: US-03 | C14: Must | D14: Là một người dùng hệ thống, tôi muốn đổi mật khẩu của chính mình, để thay được mật khẩu ban đầu hoặc mật khẩu đã bị lộ mà không cần nhờ ai khác. | E14: 2 | F14: Là hạng mục phạm vi v1.0 được nêu rõ; nhỏ và chỉ cần US-01.
B15: US-06 | C15: Must | D15: Là một thành viên Ban quản trị, tôi muốn thêm hộ gia đình mới với số căn hộ, chủ hộ, diện tích căn hộ và thông tin liên hệ, để hộ đó được tính phí đúng theo diện tích. | E15: 3 | F15: Là gốc của dữ liệu hộ; khoản thu, khoản phải thu và tìm kiếm đều phụ thuộc vào nó.
B16: US-10 | C16: Must | D16: Là một thành viên Ban quản trị, tôi muốn thêm một nhân khẩu vào hộ gia đình với họ tên, ngày sinh, giới tính, quan hệ với chủ hộ và số giấy tờ tùy thân nếu có, để danh sách nhân khẩu của hộ đầy đủ, dùng được ngay khi cần báo cáo. | E16: 3 | F16: Dữ liệu nhân khẩu dựa trên hộ gia đình; biến động và tạm trú cần nó.
B17: US-07 | C17: Must | D17: Là một thành viên Ban quản trị, tôi muốn xem chi tiết một hộ gia đình cùng danh sách nhân khẩu của hộ, để xem được ai đang ở trong căn hộ và các thông tin tính phí của hộ ở cùng một chỗ. | E17: 3 | F17: Cần dữ liệu hộ gia đình và nhân khẩu được tạo trong sprint này.
B18: US-08 | C18: Must | D18: Là một thành viên Ban quản trị, tôi muốn sửa diện tích, chủ hộ hoặc thông tin liên hệ của một hộ gia đình, để khoản thu được tính trên dữ liệu đúng và sai sót sửa được. | E18: 2 | F18: Sửa diện tích sớm giúp tránh khoản phải thu sai ở Sprint 2.
B19: US-11 | C19: Must | D19: Là một thành viên Ban quản trị, tôi muốn cập nhật thông tin của một nhân khẩu, để hồ sơ nhân khẩu luôn đúng và người đã rời đi không bị xóa khỏi hệ thống. | E19: 2 | F19: Cùng dữ liệu với US-10; hoàn thiện việc cập nhật nhân khẩu.
B20: US-12 | C20: Must | D20: Là một thành viên Ban quản trị, tôi muốn ghi nhận nhân khẩu chuyển đến, chuyển đi, sinh hoặc mất kèm ngày và lý do, để danh sách nhân khẩu từng hộ và tổng số nhân khẩu đúng với thực tế ở ngày cần xem. | E20: 5 | F20: Là story lớn nhất của Sprint 1; bắt đầu sớm để có thời gian rà soát và sửa lỗi.
B21: US-14 | C21: Must | D21: Là một thành viên Ban quản trị, tôi muốn ghi nhận tạm trú hoặc tạm vắng của một nhân khẩu kèm ngày bắt đầu, ngày kết thúc và lý do, để biết rõ tình trạng cư trú của từng người và phát hiện được các trường hợp đã hết hạn. | E21: 3 | F21: Hoàn thiện phần quản lý nhân khẩu được nêu trong đề bài.
B22: US-05 | C22: Should | D22: Là một quản trị hệ thống, tôi muốn gán cho mỗi tài khoản một vai trò, mỗi vai trò chỉ được dùng một số chức năng, để thủ quỹ chỉ làm được việc thu phí, không sửa được hộ gia đình, nhân khẩu, khoản thu, đơn giá hay tài khoản. | E22: 5 | F22: Là nền tảng cho việc kiểm tra quyền; đặt cuối sprint để áp dụng được cho các màn hình đã làm. Các màn hình sau dùng việc kiểm tra này trong các task của chính chúng.
B24: Sprint Backlog tasks
B25: Task ID | C25: US ID | D25: Task Description | E25: Assignee | F25: Reviewer | G25: Estimate (h) | H25: Dependency | I25: Deliverable | J25: Status | K25: Notes
B26: S1-T01 | C26: — | D26: Thiết lập repository dùng chung với nhánh main, quy tắc đặt tên nhánh và mẫu pull request (docs/02, mục 7) | E26: Châu Tuấn | F26: Thanh Tuấn | G26: 4 | H26: — | I26: Repository có mẫu PR và quy tắc nhánh trong README | J26: Todo | K26: Xuyên suốt. Cần nhóm thống nhất SQ-03 trước. Kế hoạch này không tạo GitHub Project.
B27: S1-T02 | C27: — | D27: Tạo khung dự án desktop Java với các package cho màn hình, service và truy cập dữ liệu | E27: Thành Nam | F27: Đức Quang | G27: 6 | H27: S1-T01 | I27: Dự án rỗng build được trong repository | J27: Todo | K27: Cross-cutting.
B28: S1-T03 | C28: — | D28: Chuẩn bị mẫu cấu hình kết nối MySQL (không chứa thông tin đăng nhập thật) và quy tắc đặt tên cho các script schema | E28: Đức Quang | F28: Mạnh Trường | G28: 4 | H28: S1-T02 | I28: Mẫu cấu hình, mục .gitignore cho file cấu hình cục bộ, thư mục script | J28: Todo | K28: Cross-cutting.
B29: S1-T04 | C29: — | D29: Xây dựng cửa sổ chính với menu điều hướng và các vùng giữ chỗ trống cho Hộ gia đình, Nhân khẩu, Khoản thu, Tìm kiếm và Thống kê | E29: Tiến Thành | F29: Thành Nam | G29: 6 | H29: S1-T02 | I29: Cửa sổ chính mở ra sau khi đăng nhập | J29: Todo | K29: Cross-cutting.
B30: S1-T05 | C30: — | D30: Hoàn thiện danh sách kiểm Definition of Done cho các task code và mẫu bản ghi kết quả kiểm thử | E30: Thanh Tuấn | F30: Châu Tuấn | G30: 3 | H30: — | I30: Mục DoD được cập nhật trong docs/02 và mẫu kết quả kiểm thử | J30: Todo | K30: Xuyên suốt. DoD là bản nháp trong docs/02 cho đến khi bắt đầu viết code.
B31: S1-T06 | C31: US-01 | D31: Tạo bảng tài khoản (tên đăng nhập, mã băm mật khẩu, vai trò, cờ hoạt động) cùng script SQL | E31: Đức Quang | F31: Mạnh Trường | G31: 3 | H31: S1-T03 | I31: Script SQL cho bảng tài khoản | J31: Todo | K31: —
B32: S1-T07 | C32: US-01 | D32: Cài đặt tiện ích băm mật khẩu có salt và kiểm tra mật khẩu | E32: Thành Nam | F32: Đức Quang | G32: 4 | H32: S1-T02 | I32: Tiện ích băm kèm một bài test ngắn | J32: Todo | K32: Cũng cung cấp AC-US02-01 (mật khẩu chỉ được lưu dưới dạng mã băm); US-02 xây dựng trên đó.
B33: S1-T08 | C33: US-01 | D33: Nạp sẵn tài khoản quản trị ban đầu từ một cấu hình cục bộ để không commit mật khẩu nào | E33: Đức Quang | F33: Mạnh Trường | G33: 2 | H33: S1-T06, S1-T07 | I33: Script nạp dữ liệu và ghi chú về nơi đặt mật khẩu ban đầu | J33: Todo | K33: Tài khoản quản trị nạp sẵn là một giả định (xem ghi chú Product_Backlog của US-41).
B34: S1-T09 | C34: US-01 | D34: Xây dựng màn hình đăng nhập (tên đăng nhập, mật khẩu, nút đăng nhập) với nhãn tiếng Việt | E34: Tiến Thành | F34: Thành Nam | G34: 4 | H34: S1-T04 | I34: Màn hình đăng nhập | J34: Todo | K34: —
B35: S1-T10 | C35: US-01 | D35: Cài đặt việc kiểm tra thông tin đăng nhập, một thông báo lỗi chung cho mọi trường hợp thất bại và việc chặn mọi màn hình quản lý trước khi đăng nhập | E35: Thành Nam | F35: Đức Quang | G35: 4 | H35: S1-T06, S1-T07, S1-T08, S1-T09 | I35: Luồng đăng nhập chạy được | J35: Todo | K35: —
B36: S1-T11 | C36: US-01 | D36: Viết và chạy test case cho AC-US01-01..03 và ghi lại kết quả | E36: Châu Tuấn | F36: Tiến Thành | G36: 3 | H36: S1-T10, S1-T05 | I36: Biên bản kiểm thử cho US-01 | J36: Todo | K36: —
B37: S1-T12 | C37: US-02 | D37: Đếm số lần đăng nhập sai liên tiếp của từng tài khoản và khóa tài khoản trong một khoảng thời gian sau khi đạt giới hạn | E37: Đức Quang | F37: Thành Nam | G37: 6 | H37: S1-T10 | I37: Logic khóa đọc giới hạn và thời gian từ cấu hình | J37: Todo | K37: Giới hạn 5 và thời gian khóa là đề xuất, chưa chốt (NFR-001.3).
... B80: S1-T55 | C80: — | D80: Chuẩn bị buổi demo cho Sprint 1 Review và cập nhật bảng công việc với những gì đã đạt Done | E80: Châu Tuấn | F80: Thanh Tuấn | G80: 2 | H80: S1-T52, S1-T53, S1-T54 | I80: Kịch bản demo và bảng công việc đã cập nhật | J80: Todo | K80: Cross-cutting.

Sheet Sprint_2
B1: Sprint 2 — Quản lý khoản thu và thu phí
B2: Ước lượng tính theo giờ (số nguyên) và là ước lượng lập kế hoạch ban đầu. Các task được liệt kê theo thứ tự làm việc. Mọi task bắt đầu ở trạng thái Todo; chưa có task nào được đánh dấu Done.
B3: Sprint Name | D3: Sprint 2 — Quản lý khoản thu và thu phí
B4: Sprint Goal | D4: Để người thu phí định nghĩa các khoản thu, tạo khoản phải thu của từng hộ và ghi nhận thanh toán đủ, một phần và tự nguyện với trạng thái thanh toán đúng, để Ban quản trị không còn phải tính và theo dõi thanh toán bằng tay. Có thể sửa các thanh toán và biên lai sai, và quản trị viên quản lý được tài khoản.
B5: Expected Increment | D5: Khoản thu có thể được tạo, thay đổi và dừng mà không mất lịch sử đơn giá. Khoản phải thu theo hộ và theo kỳ được tạo kèm bảng diễn giải rõ ràng. Thanh toán (đủ, một phần, tự nguyện) được ghi nhận và trạng thái thanh toán được cập nhật; thanh toán sai có thể được sửa hoặc hủy kèm lý do; có thể in biên lai. Quản trị viên tạo và vô hiệu hóa được tài khoản và đặt lại mật khẩu. Tất cả đều xây dựng trên dữ liệu hộ gia đình và tài khoản của Sprint 1.
B6: Total Story Points | D6: =SUM(E12:E21) -> 37
B7: Total Estimate (hours) | D7: =SUM(G25:G70) -> 174
B8: Stories / Tasks | D8: 10 story, 46 task
B9: Sprint length and dates | D9: Chưa chốt. docs/02 đề xuất một tuần, nhưng độ dài và hạn nộp vẫn là câu hỏi mở (SQ-02). Kế hoạch này không giả định ngày nào.
B10: Các story cam kết trong sprint này (từ Product_Backlog)
B11: US ID | C11: MoSCoW | D11: User Story | E11: Story Points | F11: Why in this sprint
B12: US-16 | C12: Must | D12: Là một thành viên Ban quản trị, tôi muốn tạo một khoản thu với tên, loại (bắt buộc hoặc tự nguyện), kỳ thu hoặc đợt thu, đơn giá hoặc số tiền, và hạn nộp, để các khoản tiền hộ phải đóng hoặc có thể đóng chỉ cần khai báo một lần trong hệ thống. | E12: 3 | F12: Khoản thu phải có trước khi tạo khoản phải thu hoặc thanh toán. Không phụ thuộc Sprint 1 ngoài việc đăng nhập.
B13: US-17 | C13: Must | D13: Là một thành viên Ban quản trị, tôi muốn thay đổi đơn giá hoặc hạn nộp của một khoản thu và ngừng áp dụng một khoản thu, để khoản thu cập nhật theo quyết định của Ban và thay đổi đơn giá, mà hồ sơ cũ vẫn còn. | E13: 3 | F13: Việc quản lý phiên bản đơn giá phải có trước khi tạo khoản phải thu.
B14: US-19 | C14: Must | D14: Là một thành viên Ban quản trị, tôi muốn sinh số tiền mỗi hộ phải đóng cho một kỳ thu, tính từ diện tích căn hộ và đơn giá, để không phải tính phí bằng tay và tránh được sai sót khi tính. | E14: 5 | F14: Cần hộ gia đình (Sprint 1) và khoản thu; thanh toán cần khoản phải thu.
B15: US-20 | C15: Should | D15: Là một thủ quỹ, tôi muốn xem số tiền phải đóng của một hộ gia đình được tính như thế nào, để giải thích được số tiền đó cho hộ đang thắc mắc. | E15: 2 | F15: Là màn hình nhỏ xây trên US-19; rẻ khi US-19 vừa làm xong.
B16: US-22 | C16: Must | D16: Là một thủ quỹ, tôi muốn ghi nhận thanh toán của một hộ gia đình cho một khoản thu kèm số tiền, ngày nộp và hình thức thanh toán, để có bản ghi thanh toán chính xác và trạng thái đóng phí luôn được cập nhật. | E16: 5 | F16: Là luồng nghiệp vụ trung tâm; cần khoản phải thu.
B17: US-23 | C17: Must | D17: Là một thủ quỹ, tôi muốn ghi nhận một thanh toán nhỏ hơn số tiền phải đóng và ghi nhận phần còn lại sau, để theo dõi đúng các hộ đóng làm nhiều lần và luôn thấy khoản còn nợ. | E17: 3 | F17: Xây dựng trên US-22; thanh toán thiếu là trường hợp có thật.
B18: US-21 | C18: Must | D18: Là một thành viên Ban quản trị, tôi muốn tổ chức một đợt đóng góp tự nguyện trong đó mỗi hộ tự chọn số tiền của mình, để hộ nào không đóng góp thì không bị tính là còn nợ. | E18: 3 | F18: Cần khoản thu và luồng ghi nhận thanh toán.
B19: US-26 | C19: Should | D19: Là một thủ quỹ, tôi muốn sửa hoặc hủy một thanh toán ghi sai và nêu lý do, để sửa được sai sót mà không mất lịch sử, tránh tranh chấp. | E19: 5 | F19: Xây dựng trên US-22; mở khóa các trường hợp thanh toán đã hủy trong các story ở Sprint 3.
B20: US-25 | C20: Should | D20: Là một thủ quỹ, tôi muốn in hoặc xuất biên lai cho một thanh toán đã ghi nhận, để hộ gia đình có chứng từ nộp tiền rõ ràng và thủ quỹ không phải viết biên lai bằng tay nữa. | E20: 3 | F20: Cần các thanh toán đã ghi nhận và trạng thái đã hủy của US-26.
B21: US-41 | C21: Should | D21: Là một quản trị hệ thống, tôi muốn tạo và vô hiệu hóa tài khoản cho nhân sự Ban quản trị và đặt mật khẩu mới cho người dùng quên mật khẩu, để chỉ người do Ban quản trị chọn mới đăng nhập được và nhân sự quên mật khẩu không bị khóa ngoài hệ thống. | E21: 5 | F21: Cần đăng nhập và vai trò từ Sprint 1. Đặt ở Sprint 2 để Sprint 1 có khối lượng tương đương các sprint khác; buổi demo Sprint 1 dùng tài khoản quản trị nạp sẵn.
B23: Sprint Backlog tasks
B24: Task ID | C24: US ID | D24: Task Description | E24: Assignee | F24: Reviewer | G24: Estimate (h) | H24: Dependency | I24: Deliverable | J24: Status | K24: Notes
B25: S2-T01 | C25: US-16 | D25: Thiết kế bảng khoản thu (tên, loại bắt buộc hay tự nguyện, kỳ hoặc đợt, đơn giá hoặc số tiền, hạn nộp, trạng thái) và viết script cho bảng | E25: Đức Quang | F25: Mạnh Trường | G25: 3 | H25: — | I25: Script SQL cho bảng khoản thu | J25: Todo | K25: Miễn giảm và giá đặc biệt không nằm trong v1.0 (OQ-02, OQ-03).
B26: S2-T02 | C26: US-16 | D26: Xây dựng form tạo khoản thu có các trường thay đổi theo loại khoản thu | E26: Tiến Thành | F26: Đức Quang | G26: 4 | H26: S2-T01 | I26: Màn hình tạo khoản thu | J26: Todo | K26: —
B27: S2-T03 | C27: US-16 | D27: Cài đặt việc kiểm tra dữ liệu theo loại khoản thu và chặn khoản thu trùng trong cùng kỳ | E27: Thành Nam | F27: Đức Quang | G27: 4 | H27: S2-T01, S2-T02 | I27: Chức năng tạo khoản thu chạy được | J27: Todo | K27: —
B28: S2-T04 | C28: US-16 | D28: Viết và chạy test case cho AC-US16-01..04 | E28: Mạnh Trường | F28: Tiến Thành | G28: 3 | H28: S2-T03 | I28: Biên bản kiểm thử cho US-16 | J28: Todo | K28: —
B29: S2-T05 | C29: US-17 | D29: Thêm quản lý phiên bản đơn giá để các khoản phải thu đã tạo giữ nguyên đơn giá lúc được tạo | E29: Mạnh Trường | F29: Thành Nam | G29: 4 | H29: S2-T01 | I29: Script SQL và quy tắc dữ liệu | J29: Todo | K29: —
B30: S2-T06 | C30: US-17 | D30: Xây dựng form sửa khoản thu kèm thao tác vô hiệu hóa | E30: Tiến Thành | F30: Mạnh Trường | G30: 3 | H30: S2-T03 | I30: Màn hình sửa khoản thu | J30: Todo | K30: —
B31: S2-T07 | C31: US-17 | D31: Cài đặt việc đổi giá hoặc hạn nộp, dừng một khoản thu và chặn xóa khoản thu đã được sử dụng | E31: Thành Nam | F31: Đức Quang | G31: 6 | H31: S2-T05, S2-T06 | I31: Chức năng sửa và vô hiệu hóa chạy được | J31: Todo | K31: —
B32: S2-T08 | C32: US-17 | D32: Viết và chạy test case cho AC-US17-01..03 | E32: Châu Tuấn | F32: Thành Nam | G32: 3 | H32: S2-T07 | I32: Biên bản kiểm thử cho US-17 | J32: Todo | K32: —
B33: S2-T09 | C33: US-19 | D33: Thống nhất với PO quy tắc làm tròn VND và ghi vào phần ghi chú AC (hiện chưa chốt) | E33: Thanh Tuấn | F33: Châu Tuấn | G33: 2 | H33: — | I33: Ghi chú quy tắc làm tròn | J33: Todo | K33: —
B34: S2-T10 | C34: US-19 | D34: Thiết kế bảng khoản phải thu (hộ, khoản thu, số tiền phải đóng, diện tích đã lưu, đơn giá và cách làm tròn) | E34: Mạnh Trường | F34: Đức Quang | G34: 3 | H34: S2-T01, US-06 (Sprint 1) | I34: Script SQL cho bảng khoản phải thu | J34: Todo | K34: —
B35: S2-T11 | C35: US-19 | D35: Cài đặt phép tính số tiền diện tích × đơn giá với cách làm tròn đã thống nhất | E35: Mạnh Trường | F35: Thành Nam | G35: 6 | H35: S2-T09, S2-T10, S2-T05, US-06 (Sprint 1) | I35: Chức năng tính tiền chạy được | J35: Todo | K35: —
B36: S2-T12 | C36: US-19 | D36: Cài đặt việc chống trùng cho cùng khoản thu và kỳ | E36: Đức Quang | F36: Mạnh Trường | G36: 3 | H36: S2-T11 | I36: Chức năng kiểm tra trùng chạy được | J36: Todo | K36: —
... B70: S2-T46 | C70: — | D70: Chuẩn bị buổi demo cho Sprint 2 Review và cập nhật bảng công việc với những gì đã đạt Done | E70: Châu Tuấn | F70: Thanh Tuấn | G70: 2 | H70: S2-T43, S2-T44, S2-T45 | I70: Kịch bản demo và bảng công việc đã cập nhật | J70: Todo | K70: Cross-cutting.

Sheet Sprint_3
B1: Sprint 3 — Tìm kiếm, thống kê và ổn định hóa
B2: Ước lượng tính theo giờ (số nguyên) và là ước lượng lập kế hoạch ban đầu. Các task được liệt kê theo thứ tự làm việc. Mọi task bắt đầu ở trạng thái Todo; chưa có task nào được đánh dấu Done.
B3: Sprint Name | D3: Sprint 3 — Tìm kiếm, thống kê và ổn định hóa
B4: Sprint Goal | D4: Để Ban quản trị tìm nhanh bất kỳ hộ hoặc nhân khẩu nào, xem một hộ còn nợ bao nhiêu, liệt kê hộ chưa đóng và xem thống kê thu phí và đóng góp, giữ dữ liệu cá nhân và tài chính được bảo vệ và khôi phục được, và đưa v1.0 đến trạng thái đã kiểm thử, có tài liệu và trình diễn được.
B5: Expected Increment | D5: Tìm kiếm hộ và nhân khẩu, màn hình tổng quan khoản thu theo từng hộ kèm lịch sử thanh toán, danh sách hộ chưa đóng, thống kê thu phí và thống kê các đợt đóng góp tự nguyện. Số giấy tờ được che với các vai trò không có quyền, và quản trị viên sao lưu và khôi phục được toàn bộ dữ liệu. Các mục tiêu về thời gian phản hồi và tính dễ dùng được kiểm tra trên bộ dữ liệu trình diễn. Toàn bộ ứng dụng được kiểm thử hồi quy theo Acceptance Criteria, các lỗi đã biết được sửa hoặc liệt kê, và hướng dẫn sử dụng, hướng dẫn cài đặt và ghi chú phát hành được hoàn thiện.
B6: Total Story Points | D6: =SUM(E12:E21) -> 35
B7: Total Estimate (hours) | D7: =SUM(G25:G73) -> 195
B8: Stories / Tasks | D8: 10 story, 49 task
B9: Sprint length and dates | D9: Chưa chốt. docs/02 đề xuất một tuần, nhưng độ dài và hạn nộp vẫn là câu hỏi mở (SQ-02). Kế hoạch này không giả định ngày nào.
B10: Các story cam kết trong sprint này (từ Product_Backlog)
B11: US ID | C11: MoSCoW | D11: User Story | E11: Story Points | F11: Why in this sprint
B12: US-27 | C12: Must | D12: Là một thủ quỹ, tôi muốn tìm một hộ gia đình theo số căn hộ hoặc tên chủ hộ, để phục vụ nhanh các hộ đang chờ ở quầy và biết ngay họ còn nợ gì. | E12: 3 | F12: Cần hộ gia đình và khoản phải thu để hiển thị số tiền còn nợ.
B13: US-29 | C13: Must | D13: Là một thủ quỹ, tôi muốn xem các khoản thu của một hộ (đã đóng, đóng một phần hoặc chưa đóng) và lịch sử thanh toán của hộ, để báo ngay cho hộ biết họ còn phải đóng những gì. | E13: 5 | F13: Cần thanh toán, thanh toán một phần và các thanh toán đã hủy từ Sprint 2.
B14: US-31 | C14: Must | D14: Là một thành viên Ban quản trị, tôi muốn lập danh sách các hộ chưa đóng hoặc còn nợ một khoản thu bắt buộc trong một kỳ đã chọn, để biết cần nhắc những hộ nào. | E14: 3 | F14: Cần trạng thái thanh toán từ Sprint 2.
B15: US-32 | C15: Must | D15: Là một thành viên Ban quản trị, tôi muốn xem tổng số đã thu và số còn phải thu theo khoản thu và theo tháng, để nắm nhanh tình hình thu phí và báo cáo lại được cho cư dân. | E15: 5 | F15: Cần các thanh toán đã ghi nhận và đã hủy từ Sprint 2.
B16: US-33 | C16: Must | D16: Là một thành viên Ban quản trị, tôi muốn xem với mỗi đợt đóng góp tự nguyện tổng số tiền đã đóng góp và các hộ đã đóng góp, để báo cáo rõ đã quyên góp được bao nhiêu và từ những ai. | E16: 3 | F16: Cần các thanh toán tự nguyện từ Sprint 2.
B17: US-28 | C17: Should | D17: Là một thành viên Ban quản trị, tôi muốn tìm một nhân khẩu theo họ tên hoặc thông tin cơ bản trong tất cả các hộ, để xác định nhanh một người khi cư dân hoặc cơ quan chức năng hỏi. | E17: 2 | F17: Cần nhân khẩu từ Sprint 1; ít công sức.
B18: US-39 | C18: Should | D18: Là một thủ quỹ, tôi muốn các màn hình tìm kiếm hộ gia đình, nhân khẩu và danh sách phản hồi trong vài giây, để các hộ xếp hàng ở quầy được phục vụ nhanh, không phải chờ lâu. | E18: 3 | F18: Chỉ đo được sau khi các chức năng tìm kiếm đã có.
B19: US-40 | C19: Should | D19: Là một thành viên Ban quản trị, tôi muốn ứng dụng dùng tiếng Việt, hiển thị tiền VND dễ đọc và có thông báo lỗi rõ ràng, để nhân sự không chuyên CNTT dùng được sau một buổi hướng dẫn ngắn. | E19: 3 | F19: Rà soát mọi màn hình nên phải làm sau khi chúng đã có.
B20: US-38 | C20: Should | D20: Là một quản trị hệ thống, tôi muốn sao lưu toàn bộ dữ liệu hệ thống bằng một thao tác, hoặc tự động theo lịch, và khôi phục khi cần, để hồ sơ khoản thu và nhân khẩu khôi phục được sau sự cố ổ đĩa hoặc khi lỡ xóa mất dữ liệu. | E20: 5 | F20: Các stakeholder coi sao lưu là bắt buộc (WISH-07) và RAW-026 có gợi ý Must; story cần vai trò từ Sprint 1. Đặt ở Sprint 3 để bài kiểm thử khôi phục bao phủ toàn bộ mô hình dữ liệu.
B21: US-35 | C21: Should | D21: Là một thành viên Ban quản trị, tôi muốn số giấy tờ tùy thân được che sẵn trên màn hình, chỉ vai trò được phép mới xem đầy đủ hoặc xuất ra được, để dữ liệu cá nhân của cư dân không bị lộ cho người đứng gần màn hình hoặc người không có quyền. | E21: 3 | F21: RAW-024 có gợi ý Must và cư dân lo ngại bị lộ thông tin (WISH-23). Story cần dữ liệu nhân khẩu của Sprint 1 và các màn hình tìm kiếm của Sprint 3, để việc che bao phủ mọi danh sách.
B23: Sprint Backlog tasks
B24: Task ID | C24: US ID | D24: Task Description | E24: Assignee | F24: Reviewer | G24: Estimate (h) | H24: Dependency | I24: Deliverable | J24: Status | K24: Notes
B25: S3-T01 | C25: US-27 | D25: Xây dựng ô tìm kiếm hộ gia đình và danh sách kết quả, gồm cả chế độ xem tất cả hộ theo thứ tự số căn hộ | E25: Tiến Thành | F25: Thành Nam | G25: 4 | H25: — | I25: Màn hình tìm kiếm hộ gia đình | J25: Todo | K25: —
B26: S3-T02 | C26: US-27 | D26: Cài đặt tìm theo số căn hộ và theo tên chủ hộ, kèm thông báo khi không có kết quả | E26: Đức Quang | F26: Mạnh Trường | G26: 4 | H26: S3-T01 | I26: Chức năng tìm kiếm hộ gia đình chạy được | J26: Todo | K26: —
B27: S3-T03 | C27: US-27 | D27: Hiển thị tổng số tiền còn nợ của hộ trong từng kết quả tìm kiếm | E27: Mạnh Trường | F27: Thành Nam | G27: 3 | H27: S3-T02, US-19 (Sprint 2) | I27: Số tiền còn nợ trong kết quả | J27: Todo | K27: —
B28: S3-T04 | C28: US-27 | D28: Viết và chạy test case cho AC-US27-01..04 | E28: Thanh Tuấn | F28: Đức Quang | G28: 3 | H28: S3-T03 | I28: Biên bản kiểm thử cho US-27 | J28: Todo | K28: —
B29: S3-T05 | C29: US-29 | D29: Cài đặt các truy vấn trạng thái của từng khoản thu (đã đóng, đóng một phần, chưa đóng) và lịch sử thanh toán của một hộ | E29: Thành Nam | F29: Đức Quang | G29: 6 | H29: US-22 (Sprint 2), US-23 (Sprint 2) | I29: Các truy vấn chạy được | J29: Todo | K29: —
B30: S3-T06 | C30: US-29 | D30: Xây dựng màn hình tổng quan khoản thu của hộ (khoản thu, số tiền phải đóng, đã đóng, còn lại, trạng thái) | E30: Tiến Thành | F30: Thành Nam | G30: 6 | H30: S3-T05 | I30: Màn hình tổng quan khoản thu của hộ | J30: Todo | K30: —
B31: S3-T07 | C31: US-29 | D31: Xây dựng danh sách lịch sử thanh toán, đánh dấu các thanh toán đã hủy | E31: Mạnh Trường | F31: Tiến Thành | G31: 4 | H31: S3-T05, US-26 (Sprint 2) | I31: Danh sách lịch sử thanh toán | J31: Todo | K31: —
B32: S3-T08 | C32: US-29 | D32: Viết và chạy test case cho AC-US29-01..03 | E32: Châu Tuấn | F32: Tiến Thành | G32: 4 | H32: S3-T06, S3-T07 | I32: Biên bản kiểm thử cho US-29 | J32: Todo | K32: —
B33: S3-T09 | C33: US-31 | D33: Cài đặt truy vấn các hộ còn số tiền lớn hơn 0 cho một khoản thu và kỳ được chọn, chỉ tính khoản thu bắt buộc | E33: Đức Quang | F33: Thành Nam | G33: 4 | H33: US-22 (Sprint 2), US-21 (Sprint 2) | I33: Truy vấn hộ chưa đóng chạy được | J33: Todo | K33: —
B34: S3-T10 | C34: US-31 | D34: Xây dựng danh sách hộ chưa đóng với bộ lọc theo khoản thu và kỳ | E34: Tiến Thành | F34: Đức Quang | G34: 4 | H34: S3-T09 | I34: Màn hình danh sách hộ chưa đóng | J34: Todo | K34: —
B35: S3-T11 | C35: US-31 | D35: Viết và chạy test case cho AC-US31-01..03 | E35: Thanh Tuấn | F35: Đức Quang | G35: 3 | H35: S3-T10 | I35: Biên bản kiểm thử cho US-31 | J35: Todo | K35: —
B36: S3-T12 | C36: US-32 | D36: Cài đặt việc tính tổng số tiền đã thu và còn lại theo khoản thu và theo tháng, không tính các thanh toán đã hủy | E36: Thành Nam | F36: Đức Quang | G36: 6 | H36: US-22 (Sprint 2), US-26 (Sprint 2) | I36: Các truy vấn thống kê chạy được | J36: Todo | K36: —
... B73: S3-T49 | C73: — | D73: Chuẩn bị kịch bản demo cuối cùng và buổi Sprint 3 Review | E73: Châu Tuấn | F73: Thanh Tuấn | G73: 3 | H73: S3-T46, S3-T48, S3-T47, S3-T45 | I73: Kịch bản demo và bảng công việc đã cập nhật | J73: Todo | K73: Cross-cutting.

Sheet Workload_Summary
B1: Workload Summary — số task và ước lượng (giờ) của từng thành viên
B3: Member | C3: Sprint 1 Tasks | D3: Sprint 1 Estimate | E3: Sprint 2 Tasks | F3: Sprint 2 Estimate | G3: Sprint 3 Tasks | H3: Sprint 3 Estimate | I3: Total Tasks | J3: Total Estimate | K3: Scrum Role | L3: Share of Total Estimate | M3: Tasks as Reviewer
B4: Châu Tuấn | C4: =COUNTIF(Sprint_1!$E$26:$E$80,$B4) -> 9 | D4: =SUMIF(Sprint_1!$E$26:$E$80,$B4,Sprint_1!$G$26:$G$80) -> 26 | E4: =COUNTIF(Sprint_2!$E$25:$E$70,$B4) -> 6 | F4: =SUMIF(Sprint_2!$E$25:$E$70,$B4,Sprint_2!$G$25:$G$70) -> 19 | G4: =COUNTIF(Sprint_3!$E$25:$E$73,$B4) -> 9 | H4: =SUMIF(Sprint_3!$E$25:$E$73,$B4,Sprint_3!$G$25:$G$73) -> 29 | I4: =C4+E4+G4 -> 24 | J4: =D4+F4+H4 -> 74 | K4: Scrum Master | L4: =J4/$J$10 -> 0.1295972 | M4: =COUNTIF(Sprint_1!$F$26:$F$80,$B4)+COUNTIF(Sprint_2!$F$25:$F$70,$B4)+COUNTIF(Sprint_3!$F$25:$F$73,$B4) -> 25
B5: Thanh Tuấn | C5: =COUNTIF(Sprint_1!$E$26:$E$80,$B5) -> 10 | D5: =SUMIF(Sprint_1!$E$26:$E$80,$B5,Sprint_1!$G$26:$G$80) -> 28 | E5: =COUNTIF(Sprint_2!$E$25:$E$70,$B5) -> 9 | F5: =SUMIF(Sprint_2!$E$25:$E$70,$B5,Sprint_2!$G$25:$G$70) -> 22 | G5: =COUNTIF(Sprint_3!$E$25:$E$73,$B5) -> 11 | H5: =SUMIF(Sprint_3!$E$25:$E$73,$B5,Sprint_3!$G$25:$G$73) -> 36 | I5: =C5+E5+G5 -> 30 | J5: =D5+F5+H5 -> 86 | K5: Product Owner | L5: =J5/$J$10 -> 0.15061296 | M5: =COUNTIF(Sprint_1!$F$26:$F$80,$B5)+COUNTIF(Sprint_2!$F$25:$F$70,$B5)+COUNTIF(Sprint_3!$F$25:$F$73,$B5) -> 12
B6: Thành Nam | C6: =COUNTIF(Sprint_1!$E$26:$E$80,$B6) -> 9 | D6: =SUMIF(Sprint_1!$E$26:$E$80,$B6,Sprint_1!$G$26:$G$80) -> 46 | E6: =COUNTIF(Sprint_2!$E$25:$E$70,$B6) -> 6 | F6: =SUMIF(Sprint_2!$E$25:$E$70,$B6,Sprint_2!$G$25:$G$70) -> 29 | G6: =COUNTIF(Sprint_3!$E$25:$E$73,$B6) -> 7 | H6: =SUMIF(Sprint_3!$E$25:$E$73,$B6,Sprint_3!$G$25:$G$73) -> 34 | I6: =C6+E6+G6 -> 22 | J6: =D6+F6+H6 -> 109 | K6: Developer | L6: =J6/$J$10 -> 0.19089317 | M6: =COUNTIF(Sprint_1!$F$26:$F$80,$B6)+COUNTIF(Sprint_2!$F$25:$F$70,$B6)+COUNTIF(Sprint_3!$F$25:$F$73,$B6) -> 33
B7: Đức Quang | C7: =COUNTIF(Sprint_1!$E$26:$E$80,$B7) -> 9 | D7: =SUMIF(Sprint_1!$E$26:$E$80,$B7,Sprint_1!$G$26:$G$80) -> 33 | E7: =COUNTIF(Sprint_2!$E$25:$E$70,$B7) -> 8 | F7: =SUMIF(Sprint_2!$E$25:$E$70,$B7,Sprint_2!$G$25:$G$70) -> 33 | G7: =COUNTIF(Sprint_3!$E$25:$E$73,$B7) -> 7 | H7: =SUMIF(Sprint_3!$E$25:$E$73,$B7,Sprint_3!$G$25:$G$73) -> 30 | I7: =C7+E7+G7 -> 24 | J7: =D7+F7+H7 -> 96 | K7: Developer | L7: =J7/$J$10 -> 0.16812609 | M7: =COUNTIF(Sprint_1!$F$26:$F$80,$B7)+COUNTIF(Sprint_2!$F$25:$F$70,$B7)+COUNTIF(Sprint_3!$F$25:$F$73,$B7) -> 31
B8: Mạnh Trường | C8: =COUNTIF(Sprint_1!$E$26:$E$80,$B8) -> 8 | D8: =SUMIF(Sprint_1!$E$26:$E$80,$B8,Sprint_1!$G$26:$G$80) -> 29 | E8: =COUNTIF(Sprint_2!$E$25:$E$70,$B8) -> 9 | F8: =SUMIF(Sprint_2!$E$25:$E$70,$B8,Sprint_2!$G$25:$G$70) -> 35 | G8: =COUNTIF(Sprint_3!$E$25:$E$73,$B8) -> 8 | H8: =SUMIF(Sprint_3!$E$25:$E$73,$B8,Sprint_3!$G$25:$G$73) -> 34 | I8: =C8+E8+G8 -> 25 | J8: =D8+F8+H8 -> 98 | K8: Developer | L8: =J8/$J$10 -> 0.17162872 | M8: =COUNTIF(Sprint_1!$F$26:$F$80,$B8)+COUNTIF(Sprint_2!$F$25:$F$70,$B8)+COUNTIF(Sprint_3!$F$25:$F$73,$B8) -> 31
B9: Tiến Thành | C9: =COUNTIF(Sprint_1!$E$26:$E$80,$B9) -> 10 | D9: =SUMIF(Sprint_1!$E$26:$E$80,$B9,Sprint_1!$G$26:$G$80) -> 40 | E9: =COUNTIF(Sprint_2!$E$25:$E$70,$B9) -> 8 | F9: =SUMIF(Sprint_2!$E$25:$E$70,$B9,Sprint_2!$G$25:$G$70) -> 36 | G9: =COUNTIF(Sprint_3!$E$25:$E$73,$B9) -> 7 | H9: =SUMIF(Sprint_3!$E$25:$E$73,$B9,Sprint_3!$G$25:$G$73) -> 32 | I9: =C9+E9+G9 -> 25 | J9: =D9+F9+H9 -> 108 | K9: Developer | L9: =J9/$J$10 -> 0.18914186 | M9: =COUNTIF(Sprint_1!$F$26:$F$80,$B9)+COUNTIF(Sprint_2!$F$25:$F$70,$B9)+COUNTIF(Sprint_3!$F$25:$F$73,$B9) -> 18
B10: Total | C10: =SUM(C4:C9) -> 55 | D10: =SUM(D4:D9) -> 202 | E10: =SUM(E4:E9) -> 46 | F10: =SUM(F4:F9) -> 174 | G10: =SUM(G4:G9) -> 49 | H10: =SUM(H4:H9) -> 195 | I10: =SUM(I4:I9) -> 150 | J10: =SUM(J4:J9) -> 571 | L10: =SUM(L4:L9) -> 1 | M10: =SUM(M4:M9) -> 150
B12: Cách cân bằng khối lượng
B13: Ước lượng tính theo giờ. Mỗi Developer đảm nhận 96-109 giờ trong ba sprint (chênh lệch 13% so với mức trung bình của Developer).
B14: Scrum Master và Product Owner không nhận task code (docs/02, mục 1: nhận ít task hơn). Hai vai trò này viết và chạy test case, thống nhất quy tắc với nhau, viết tài liệu và rà soát, nên tổng giờ thấp hơn là có chủ ý.
B15: Các task của một story được chia cho nhiều thành viên. Không ai rà soát task của chính mình. Task code do một Developer rà soát; Product Owner chỉ nghiệm thu một story sau khi người rà soát các task của nó đã duyệt (docs/02, mục 4).
B16: Việc phân công là đề xuất cho buổi Sprint Planning. Nhóm có thể đổi người thực hiện khi biết lịch rảnh thực tế.

Sheet Legend
B1: Legend — Product Backlog
B2: Term | C2: Meaning in this project | D2: Where used
B3: Terms
B4: Epic | C4: Một năng lực nghiệp vụ lớn gom các Feature và User Story (EPIC-01 đến EPIC-07). | D4: Product_Backlog, Traceability
B5: Feature | C5: Một phần cụ thể của Epic chứa một hoặc nhiều User Story (FEAT-xx-yy). | D5: Product_Backlog, Traceability
B6: User Story | C6: Một yêu cầu nhỏ viết theo mẫu: Là một [vai trò], tôi muốn [mục tiêu], để [giá trị nghiệp vụ] (US-xx). Technical Story là story phi chức năng. Mọi story đều được suy ra từ đề bài và kịch bản stakeholder. | D6: Product_Backlog
